<?xml version="1.0"?>
<robot name="four_wheel_robot">

  <!-- Ground reference frame -->
  <link name="base_footprint"/>

  <!-- Main robot body -->
  <link name="base_link">
    <visual>
      <geometry>
        <box size="0.6 0.4 0.2"/>
      </geometry>
      <material name="chassis_color">
        <color rgba="0.1 0.5 0.8 1.0"/>
      </material>
    </visual>

    <collision>
      <geometry>
        <box size="0.6 0.4 0.2"/>
      </geometry>
    </collision>

    <inertial>
      <mass value="5.0"/>
      <origin xyz="0 0 0" rpy="0 0 0"/>
      <inertia
        ixx="0.083333"
        ixy="0.0"
        ixz="0.0"
        iyy="0.166667"
        iyz="0.0"
        izz="0.216667"/>
    </inertial>
  </link>

  <!-- Connect the body to the ground reference frame -->
  <joint name="base_footprint_joint" type="fixed">
    <parent link="base_footprint"/>
    <child link="base_link"/>
    <origin xyz="0 0 0.15" rpy="0 0 0"/>
  </joint>

  <!-- Front-left wheel -->
  <link name="front_left_wheel_link">
    <visual>
      <origin xyz="0 0 0" rpy="1.570796 0 0"/>
      <geometry>
        <cylinder radius="0.1" length="0.05"/>
      </geometry>
      <material name="wheel_color">
        <color rgba="0.1 0.1 0.1 1.0"/>
      </material>
    </visual>

    <collision>
      <origin xyz="0 0 0" rpy="1.570796 0 0"/>
      <geometry>
        <cylinder radius="0.1" length="0.05"/>
      </geometry>
    </collision>

    <inertial>
      <mass value="0.5"/>
      <origin xyz="0 0 0" rpy="1.570796 0 0"/>
      <inertia
        ixx="0.001354"
        ixy="0.0"
        ixz="0.0"
        iyy="0.001354"
        iyz="0.0"
        izz="0.0025"/>
    </inertial>
  </link>

  <joint name="front_left_wheel_joint" type="continuous">
    <parent link="base_link"/>
    <child link="front_left_wheel_link"/>
    <origin xyz="0.2 0.225 -0.05" rpy="0 0 0"/>
    <axis xyz="0 1 0"/>
  </joint>

  <!-- Front-right wheel -->
  <link name="front_right_wheel_link">
    <visual>
      <origin xyz="0 0 0" rpy="1.570796 0 0"/>
      <geometry>
        <cylinder radius="0.1" length="0.05"/>
      </geometry>
      <material name="wheel_color">
        <color rgba="0.1 0.1 0.1 1.0"/>
      </material>
              

    </visual>

    <collision>
      <origin xyz="0 0 0" rpy="1.570796 0 0"/>
      <geometry>
        <cylinder radius="0.1" length="0.05"/>
      </geometry>
    </collision>

    <inertial>
      <mass value="0.5"/>
      <origin xyz="0 0 0" rpy="1.570796 0 0"/>
      <inertia
        ixx="0.001354"
        ixy="0.0"
        ixz="0.0"
        iyy="0.001354"
        iyz="0.0"
        izz="0.0025"/>
    </inertial>
  </link>

  <joint name="front_right_wheel_joint" type="continuous">
    <parent link="base_link"/>
    <child link="front_right_wheel_link"/>
    <origin xyz="0.2 -0.225 -0.05" rpy="0 0 0"/>
    <axis xyz="0 1 0"/>
  </joint>

  <!-- Rear-left wheel -->
  <link name="rear_left_wheel_link">
    <visual>
      <origin xyz="0 0 0" rpy="1.570796 0 0"/>
      <geometry>
        <cylinder radius="0.1" length="0.05"/>
      </geometry>
      <material name="wheel_color">
        <color rgba="0.1 0.1 0.1 1.0"/>
      </material>
    </visual>

    <collision>
      <origin xyz="0 0 0" rpy="1.570796 0 0"/>
      <geometry>
        <cylinder radius="0.1" length="0.05"/>
      </geometry>
    </collision>

    <inertial>
      <mass value="0.5"/>
      <origin xyz="0 0 0" rpy="1.570796 0 0"/>
      <inertia
        ixx="0.001354"
        ixy="0.0"
        ixz="0.0"
        iyy="0.001354"
        iyz="0.0"
        izz="0.0025"/>
    </inertial>
  </link>

  <joint name="rear_left_wheel_joint" type="continuous">
    <parent link="base_link"/>
    <child link="rear_left_wheel_link"/>
    <origin xyz="-0.2 0.225 -0.05" rpy="0 0 0"/>
    <axis xyz="0 1 0"/>
  </joint>

  <!-- Rear-right wheel -->
  <link name="rear_right_wheel_link">
    <visual>
      <origin xyz="0 0 0" rpy="1.570796 0 0"/>
      <geometry>
        <cylinder radius="0.1" length="0.05"/>
      </geometry>
      <material name="wheel_color">
        <color rgba="0.1 0.1 0.1 1.0"/>
      </material>
    </visual>

    <collision>
      <origin xyz="0 0 0" rpy="1.570796 0 0"/>
      <geometry>
        <cylinder radius="0.1" length="0.05"/>
      </geometry>
    </collision>

    <inertial>
      <mass value="0.5"/>
      <origin xyz="0 0 0" rpy="1.570796 0 0"/>
      <inertia
        ixx="0.001354"
        ixy="0.0"
        ixz="0.0"
        iyy="0.001354"
        iyz="0.0"
        izz="0.0025"/>
    </inertial>
  </link>

  <joint name="rear_right_wheel_joint" type="continuous">
    <parent link="base_link"/>
    <child link="rear_right_wheel_link"/>
    <origin xyz="-0.2 -0.225 -0.05" rpy="0 0 0"/>
    <axis xyz="0 1 0"/>
  </joint>

</robot>
