<?xml version="1.0"?>
<robot name="four_wheel_robot" xmlns:xacro="http://www.ros.org/wiki/xacro">
<xacro:include filename="$(find my_robot_description)/urdf/robot_description.gazebo"/>

<xacro:arg name="mesh_path" default="package://my_robot_description/meshes/"/>

  <xacro:property name="base_length" value="0.6"/>
  <xacro:property name="base_width" value="0.4"/>
  <xacro:property name="base_height" value="0.2"/>
  <xacro:property name="base_mass" value="5.0"/>

  <xacro:property name="wheel_radius" value="0.1"/>
  <xacro:property name="wheel_width" value="0.05"/>
  <xacro:property name="wheel_mass" value="0.5"/>

  <xacro:property name="wheel_x_offset" value="0.2"/> 
  <xacro:property name="wheel_y_offset" value="0.225"/> 
  <xacro:property name="wheel_z_offset" value="-0.05"/> 

  <link name="base_footprint"/>

  <joint name="base_footprint_joint" type="fixed">
    <parent link="base_footprint"/>
    <child link="base_link"/>
    <origin xyz="0 0 0.15" rpy="0 0 0"/>
  </joint>

  <link name="base_link">
    <visual>
      <geometry>
        <box size="${base_length} ${base_width} ${base_height}"/>
      </geometry>
      <material name="chassis_color">
        <color rgba="0.1 0.5 0.8 1.0"/>
      </material>
    </visual>
    <collision>
      <geometry>
        <box size="${base_length} ${base_width} ${base_height}"/>
      </geometry>
    </collision>
    <inertial>
      <mass value="${base_mass}"/>
      <origin xyz="0 0 0" rpy="0 0 0"/>
      <inertia ixx="${(1/12) * base_mass * (base_width*base_width + base_height*base_height)}" ixy="0.0" ixz="0.0"
               iyy="${(1/12) * base_mass * (base_length*base_length + base_height*base_height)}" iyz="0.0"
               izz="${(1/12) * base_mass * (base_length*base_length + base_width*base_width)}"/>
    </inertial>
  </link>

  <!-- LIDAR LINK - OUTSIDE MACRO (only created once) -->
  <link name="lidar_link">
    <visual>
      <origin xyz="0 0 0" rpy="0 0 0"/>
      <geometry>
        <mesh filename="$(arg mesh_path)lidar.STL"/>
      </geometry>
      <material name="lidar_gray">
        <color rgba="0.6 0.6 0.6 1.0"/>
      </material>
    </visual>
    <collision>
      <origin xyz="0 0 0" rpy="0 0 0"/>
      <geometry>
        <cylinder radius="0.06" length="0.04"/>
      </geometry>
    </collision>
    <inertial>
      <mass value="0.2"/>
      <origin xyz="0 0 0" rpy="0 0 0"/>
      <inertia ixx="0.0001" ixy="0.0" ixz="0.0"
               iyy="0.0001" iyz="0.0"
               izz="0.0001"/>
    </inertial>
  </link>

  <joint name="lidar_joint" type="fixed">
    <parent link="base_link"/>
    <child link="lidar_link"/>
    <origin xyz="0.2 0 0.13" rpy="0 0 0"/>
  </joint>

  <link name="camera_link">
  <visual>
    <origin xyz="0 0 0" rpy="0 0 0"/>
    <geometry>
      <mesh filename="$(arg mesh_path)zed.stl"/>
    </geometry>
    <material name="camera_black">
      <color rgba="0.5 0.5 0.5 1.0"/>
    </material>
  </visual>
  <collision>
    <origin xyz="0 0 0" rpy="0 0 0"/>
    <geometry>
      <box size="0.08 0.03 0.03"/>
    </geometry>
  </collision>
  <inertial>
    <mass value="0.1"/>
    <origin xyz="0 0 0" rpy="0 0 0"/>
    <inertia ixx="0.00005" ixy="0.0" ixz="0.0"
             iyy="0.00005" iyz="0.0"
             izz="0.00005"/>
  </inertial>
</link>

<joint name="camera_joint" type="fixed">
  <parent link="base_link"/>
  <child link="camera_link"/>
  <origin xyz="0.3 0 0.08" rpy="0 0 0"/>
</joint>
<link name="camera_optical_link"/>

<joint name="camera_optical_joint" type="fixed">
  <parent link="camera_link"/>
  <child link="camera_optical_link"/>
  <origin xyz="0 0 0" rpy="-1.5708 0 -1.5708"/>
</joint>


  <!-- WHEEL MACRO (without lidar inside) -->
  <xacro:macro name="wheel" params="prefix x_reflect y_reflect">
    <joint name="${prefix}_wheel_joint" type="continuous">
      <parent link="base_link"/>
      <child link="${prefix}_wheel_link"/>
      <origin xyz="${x_reflect * wheel_x_offset} ${y_reflect * wheel_y_offset} ${wheel_z_offset}" rpy="0 0 0"/>
      <axis xyz="0 1 0"/>
    </joint>

    <link name="${prefix}_wheel_link">
      <visual>
        <origin xyz="0 0 0" rpy="${pi/2} 0 0"/>
        <geometry>
          <cylinder radius="${wheel_radius}" length="${wheel_width}"/>
        </geometry>
        <material name="wheel_color">
          <color rgba="0.1 0.1 0.1 1.0"/>
        </material>
      </visual>
      <collision>
        <origin xyz="0 0 0" rpy="${pi/2} 0 0"/>
        <geometry>
          <cylinder radius="${wheel_radius}" length="${wheel_width}"/>
        </geometry>
      </collision>
      <inertial>
        <mass value="${wheel_mass}"/>
        <origin xyz="0 0 0" rpy="${pi/2} 0 0"/>
        <inertia ixx="${(1/12) * wheel_mass * (3*wheel_radius*wheel_radius + wheel_width*wheel_width)}" ixy="0.0" ixz="0.0"
                 iyy="${(1/12) * wheel_mass * (3*wheel_radius*wheel_radius + wheel_width*wheel_width)}" iyz="0.0"
                 izz="${(1/2) * wheel_mass * (wheel_radius*wheel_radius)}"/>
      </inertial>
    </link>
  </xacro:macro>

  <xacro:wheel prefix="front_left"  x_reflect="1"  y_reflect="1" />
  <xacro:wheel prefix="front_right" x_reflect="1"  y_reflect="-1" />
  <xacro:wheel prefix="rear_left"   x_reflect="-1" y_reflect="1" />
  <xacro:wheel prefix="rear_right"  x_reflect="-1" y_reflect="-1" />

</robot>
